#VRML_SIM R2022a utf8
WorldInfo {
  basicTimeStep 16
  physicsDisableTime 2
  contactProperties [
    ContactProperties {
      coulombFriction [
        0
      ]
    }
  ]
}
Viewpoint {
  orientation -0.24499060809274523 -0.05548546884063403 0.9679364466192407 3.573213203291989
  position 0.6132577403963089 0.2469258485194919 0.4584707472419278
}
TexturedBackground {
}
TexturedBackgroundLight {
}
Floor {
  size 1 1
}
Solid {
  translation -0.000923805 -0.495205 0.05
  children [
    Shape {
      appearance DEF WALL1 PBRAppearance {
        baseColorMap ImageTexture {
          url [
            "C:/Users/MSI GF63/Downloads/red_brick_wall.jpg"
          ]
        }
      }
      geometry Box {
        size 1 0.01 0.1
      }
    }
  ]
  name "solid(1)"
}
Solid {
  translation -0.000923805 0.494795 0.05
  children [
    Shape {
      appearance USE WALL1
      geometry Box {
        size 1 0.01 0.1
      }
    }
  ]
  name "solid(2)"
}
Solid {
  translation 0.499074 -0.00520304 0.05
  rotation 0 0 1 1.5708
  children [
    Shape {
      appearance USE WALL1
      geometry Box {
        size 1 0.01 0.1
      }
    }
  ]
  name "solid(3)"
}
Solid {
  translation -0.500926 -0.00520696 0.05
  rotation 0 0 1 1.5708
  children [
    Shape {
      appearance USE WALL1
      geometry Box {
        size 1 0.01 0.1
      }
    }
  ]
  name "solid(4)"
}
Solid {
  translation -0.0301809 0.00340406 0.09
  children [
    HingeJoint {
      jointParameters HingeJointParameters {
        anchor 0.5 0.6 0
      }
      endPoint DEF WHEEL Solid {
        translation -0.07 0.06 -1.22354e-07
        rotation 1 0 0 -1.5707953071795862
        children [
          Shape {
            appearance PBRAppearance {
              baseColor 0.4 0 1
              metalness 0
            }
            geometry Cylinder {
              height 0.02
              radius 0.04
            }
          }
        ]
        boundingObject Shape {
          appearance PBRAppearance {
          }
        }
        physics Physics {
        }
      }
    }
    HingeJoint {
      jointParameters HingeJointParameters {
        anchor 0.5 0.6 0
      }
      endPoint DEF WHEEL Solid {
        translation -0.07 -0.06 -2.44706e-07
        rotation 1 0 0 -1.5707953071795862
        children [
          Shape {
            appearance PBRAppearance {
              baseColor 0.4 0 1
              metalness 0
            }
            geometry Cylinder {
              height 0.02
              radius 0.04
            }
          }
        ]
        name "solid(2)"
        boundingObject Shape {
          appearance PBRAppearance {
          }
        }
        physics Physics {
        }
      }
    }
    HingeJoint {
      jointParameters HingeJointParameters {
        anchor 0.5 0.6 0
      }
      endPoint DEF WHEEL Solid {
        translation 0.06 -0.06 -2.44706e-07
        rotation 1 0 0 -1.5707953071795862
        children [
          Shape {
            appearance PBRAppearance {
              baseColor 0.4 0 1
              metalness 0
            }
            geometry DEF cyl1 Cylinder {
              height 0.02
              radius 0.04
            }
          }
        ]
        name "solid(1)"
        boundingObject Shape {
          appearance PBRAppearance {
          }
          geometry USE cyl1
        }
        physics Physics {
        }
      }
    }
    HingeJoint {
      jointParameters HingeJointParameters {
        anchor 0.5 0.6 0
      }
      endPoint DEF WHEEL Solid {
        translation 0.06 0.06 -1.22354e-07
        rotation 1 0 0 -1.5707953071795862
        children [
          Shape {
            appearance PBRAppearance {
              baseColor 0.4 0 1
              metalness 0
            }
            geometry DEF cyl1 Cylinder {
              height 0.02
              radius 0.04
            }
          }
        ]
        name "solid(3)"
        boundingObject Shape {
          appearance PBRAppearance {
          }
          geometry USE cyl1
        }
        physics Physics {
        }
      }
    }
    Shape {
      appearance PBRAppearance {
        baseColor 1 0 0
        roughness 1
        metalness 0
      }
      geometry Box {
        size 0.2 0.1 0.05
      }
    }
  ]
}
